Workbook

Sheet FINAL PAY OUT
A2: Row Labels | B2: Center Alignment | C2: NPD | D2: OSA | E2: POSM | F2: SOS vs SOM | G2: Average Score | H2: Score
A3: 2k shoppers | B3: 1 | C3: 0.77777778 | D3: 1 | E3: 1 | F3: =VLOOKUP(A:A,'SOS VS SOM'!A:E,4,FALSE) -> 0 | G3: =AVERAGE(B3:F3) -> 0.75555556 | H3: =IF(G3>=60%,"pay","don't pay") -> pay
A4: Abra Shopping Centre | B4: 1 | C4: 1 | D4: 1 | E4: 1 | F4: =VLOOKUP(A:A,'SOS VS SOM'!A:E,4,FALSE) -> 0 | G4: =AVERAGE(B4:F4) -> 0.8 | H4: =IF(G4>=60%,"pay","don't pay") -> pay
A5: Abrah supermarket | B5: 1 | C5: 0.4 | D5: 1 | E5: 1 | F5: =VLOOKUP(A:A,'SOS VS SOM'!A:E,4,FALSE) -> 0 | G5: =AVERAGE(B5:F5) -> 0.68 | H5: =IF(G5>=60%,"pay","don't pay") -> pay
A6: Active supermarket | B6: 1 | C6: 1 | D6: 1 | E6: 1 | F6: =VLOOKUP(A:A,'SOS VS SOM'!A:E,4,FALSE) -> 0 | G6: =AVERAGE(B6:F6) -> 0.8 | H6: =IF(G6>=60%,"pay","don't pay") -> pay
A7: Apple Door To Door Supermarket | B7: 1 | C7: 0.45454545 | D7: 0.85925926 | E7: 1 | F7: =VLOOKUP(A:A,'SOS VS SOM'!A:E,4,FALSE) -> 0 | G7: =AVERAGE(B7:F7) -> 0.66276094 | H7: =IF(G7>=60%,"pay","don't pay") -> pay
A8: Bam Shopping Centre | B8: 0 | C8: 0.4 | D8: 1 | E8: 1 | F8: =VLOOKUP(A:A,'SOS VS SOM'!A:E,4,FALSE) -> 1 | G8: =AVERAGE(B8:F8) -> 0.68 | H8: =IF(G8>=60%,"pay","don't pay") -> pay
A9: Bea Mart (U) Ltd | B9: 1 | C9: 0.4 | D9: 1 | E9: 1 | F9: =VLOOKUP(A:A,'SOS VS SOM'!A:E,4,FALSE) -> 1 | G9: =AVERAGE(B9:F9) -> 0.88 | H9: =IF(G9>=60%,"pay","don't pay") -> pay
A10: Benco Liner Supermarket Ltd | B10: 1 | C10: 1 | D10: 1 | E10: 1 | F10: =VLOOKUP(A:A,'SOS VS SOM'!A:E,4,FALSE) -> 0 | G10: =AVERAGE(B10:F10) -> 0.8 | H10: =IF(G10>=60%,"pay","don't pay") -> pay
A11: Bengel | B11: 1 | C11: 0.63636364 | D11: 1 | E11: 1 | F11: =VLOOKUP(A:A,'SOS VS SOM'!A:E,4,FALSE) -> 1 | G11: =AVERAGE(B11:F11) -> 0.92727273 | H11: =IF(G11>=60%,"pay","don't pay") -> pay
A12: Best Buy Bukoto | B12: 1 | C12: 0.85 | D12: 0.9962963 | E12: 1 | F12: =VLOOKUP(A:A,'SOS VS SOM'!A:E,4,FALSE) -> 0 | G12: =AVERAGE(B12:F12) -> 0.76925926 | H12: =IF(G12>=60%,"pay","don't pay") -> pay
A13: CAC KYANJA | B13: 1 | C13: 0.55 | D13: 0.97083333 | E13: 1 | F13: =VLOOKUP(A:A,'SOS VS SOM'!A:E,4,FALSE) -> 0 | G13: =AVERAGE(B13:F13) -> 0.70416667 | H13: =IF(G13>=60%,"pay","don't pay") -> pay
A14: Capital Shoppers Garden City | B14: 0 | C14: 0.22222222 | D14: 0.94153846 | E14: 1 | F14: =VLOOKUP(A:A,'SOS VS SOM'!A:E,4,FALSE) -> 0 | G14: =AVERAGE(B14:F14) -> 0.43275214 | H14: =IF(G14>=60%,"pay","don't pay") -> don't pay
... A29: City Joy Kitintale | B29: 1 | C29: 0.9 | D29: 1 | E29: 1 | F29: =VLOOKUP(A:A,'SOS VS SOM'!A:E,4,FALSE) -> 0 | G29: =AVERAGE(B29:F29) -> 0.78 | H29: =IF(G29>=60%,"pay","don't pay") -> pay
A30: City Joy Kitintale | B30: 1 | C30: 0.4 | D30: 1 | E30: 1 | F30: 0 | G30: =AVERAGE(B30:F30) -> 0.68 | H30: =IF(G30>=60%,"pay","don't pay") -> pay
A31: City Joy Mbuya | B31: 1 | C31: 0.64 | D31: 0.96666667 | E31: 1 | F31: =VLOOKUP(A:A,'SOS VS SOM'!A:E,4,FALSE) -> 0 | G31: =AVERAGE(B31:F31) -> 0.72133333 | H31: =IF(G31>=60%,"pay","don't pay") -> pay
A32: City joy supermarket Kireka | B32: 1 | C32: 0.4 | D32: 0.97666667 | E32: 1 | F32: =VLOOKUP(A:A,'SOS VS SOM'!A:E,4,FALSE) -> 0 | G32: =AVERAGE(B32:F32) -> 0.67533333 | H32: =IF(G32>=60%,"pay","don't pay") -> pay
A33: City Shoppers Supermarket | B33: 1 | C33: 1 | D33: 0.8047619 | E33: 1 | F33: =VLOOKUP(A:A,'SOS VS SOM'!A:E,4,FALSE) -> 0 | G33: =AVERAGE(B33:F33) -> 0.76095238 | H33: =IF(G33>=60%,"pay","don't pay") -> pay
A34: Costco | B34: 0 | C34: 0.4 | D34: 1 | E34: 1 | F34: =VLOOKUP(A:A,'SOS VS SOM'!A:E,4,FALSE) -> 0 | G34: =AVERAGE(B34:F34) -> 0.48 | H34: =IF(G34>=60%,"pay","don't pay") -> don't pay
A35: Crane Shoppers | B35: 1 | C35: 0.55 | D35: 1 | E35: 1 | F35: =VLOOKUP(A:A,'SOS VS SOM'!A:E,4,FALSE) -> 0 | G35: =AVERAGE(B35:F35) -> 0.71 | H35: =IF(G35>=60%,"pay","don't pay") -> pay
A36: Crown Stores Sonde | B36: 1 | C36: 0.44444444 | D36: 0.82380952 | E36: 1 | F36: =VLOOKUP(A:A,'SOS VS SOM'!A:E,4,FALSE) -> 0 | G36: =AVERAGE(B36:F36) -> 0.65365079 | H36: =IF(G36>=60%,"pay","don't pay") -> pay
A37: Cynibel General Trading Limited (B | B37: 1 | C37: 1 | D37: 0.99342105 | E37: 1 | F37: =VLOOKUP(A:A,'SOS VS SOM'!A:E,4,FALSE) -> 0 | G37: =AVERAGE(B37:F37) -> 0.79868421 | H37: =IF(G37>=60%,"pay","don't pay") -> pay
A38: Cynibel General Trading Ltd ( Lweza | B38: 0 | C38: 0.88888889 | D38: 1 | E38: 1 | F38: =VLOOKUP(A:A,'SOS VS SOM'!A:E,4,FALSE) -> 0 | G38: =AVERAGE(B38:F38) -> 0.57777778 | H38: =IF(G38>=60%,"pay","don't pay") -> don't pay
A39: Cynibel Kiwatule | B39: 1 | C39: 0.64705882 | D39: 0.96666667 | E39: 1 | F39: =VLOOKUP(A:A,'SOS VS SOM'!A:E,4,FALSE) -> 0 | G39: =AVERAGE(B39:F39) -> 0.7227451 | H39: =IF(G39>=60%,"pay","don't pay") -> pay
A40: Cynibel Super Market | B40: 1 | C40: 1 | D40: 0.99885584 | E40: 1 | F40: =VLOOKUP(A:A,'SOS VS SOM'!A:E,4,FALSE) -> 0 | G40: =AVERAGE(B40:F40) -> 0.79977117 | H40: =IF(G40>=60%,"pay","don't pay") -> pay
A41: Day Day life supermarket | B41: 1 | C41: 0.4 | D41: 1 | E41: 1 | F41: =VLOOKUP(A:A,'SOS VS SOM'!A:E,4,FALSE) -> 0 | G41: =AVERAGE(B41:F41) -> 0.68 | H41: =IF(G41>=60%,"pay","don't pay") -> pay
A42: Day To Day Uganda Limited | B42: 1 | C42: 0.4 | D42: 0.9122807 | E42: 1 | F42: =VLOOKUP(A:A,'SOS VS SOM'!A:E,4,FALSE) -> 0 | G42: =AVERAGE(B42:F42) -> 0.66245614 | H42: =IF(G42>=60%,"pay","don't pay") -> pay
... A46: Dine and Save | B46: 1 | C46: 1 | D46: 0.99583333 | E46: 1 | F46: =VLOOKUP(A:A,'SOS VS SOM'!A:E,4,FALSE) -> 0 | G46: =AVERAGE(B46:F46) -> 0.79916667 | H46: =IF(G46>=60%,"pay","don't pay") -> pay
A47: Dine And Save Supermarket | B47: 1 | C47: 1 | D47: 0.96666667 | E47: 1 | F47: 0 | G47: =AVERAGE(B47:F47) -> 0.79333333 | H47: =IF(G47>=60%,"pay","don't pay") -> pay
A48: Ecomart BUNGA | B48: 1 | C48: 1 | D48: 1 | E48: 1 | F48: =VLOOKUP(A:A,'SOS VS SOM'!A:E,4,FALSE) -> 0 | G48: =AVERAGE(B48:F48) -> 0.8 | H48: =IF(G48>=60%,"pay","don't pay") -> pay
A49: Ecomart Kisaasi | B49: 0 | C49: 1 | D49: 1 | E49: 1 | F49: =VLOOKUP(A:A,'SOS VS SOM'!A:E,4,FALSE) -> 0 | G49: =AVERAGE(B49:F49) -> 0.6 | H49: =IF(G49>=60%,"pay","don't pay") -> pay
A50: Ecomart Kiwatule | B50: 0 | C50: 1 | D50: 0.97235023 | E50: 1 | F50: =VLOOKUP(A:A,'SOS VS SOM'!A:E,4,FALSE) -> 0 | G50: =AVERAGE(B50:F50) -> 0.59447005 | H50: =IF(G50>=60%,"pay","don't pay") -> don't pay
A51: Ecomart Seguku | B51: 1 | C51: 1 | D51: 0.99108138 | E51: 1 | F51: =VLOOKUP(A:A,'SOS VS SOM'!A:E,4,FALSE) -> 0 | G51: =AVERAGE(B51:F51) -> 0.79821628 | H51: =IF(G51>=60%,"pay","don't pay") -> pay
A52: Embassy supermarket LUBOWA | B52: 0 | C52: 1 | D52: 0.97407407 | E52: 1 | F52: =VLOOKUP(A:A,'SOS VS SOM'!A:E,4,FALSE) -> 0 | G52: =AVERAGE(B52:F52) -> 0.59481481 | H52: =IF(G52>=60%,"pay","don't pay") -> don't pay
A53: Equity Shoppers Supermarket | B53: 1 | C53: 1 | D53: 0.96666667 | E53: 1 | F53: =VLOOKUP(A:A,'SOS VS SOM'!A:E,4,FALSE) -> 1 | G53: =AVERAGE(B53:F53) -> 0.99333333 | H53: =IF(G53>=60%,"pay","don't pay") -> pay
A54: Fabulous Freeman | B54: 0 | C54: 0.59090909 | D54: 1 | E54: 1 | F54: 0 | G54: =AVERAGE(B54:F54) -> 0.51818182 | H54: =IF(G54>=60%,"pay","don't pay") -> don't pay
A55: Fabulous Freeman Supermarket | B55: 0 | C55: 0.4 | D55: 1 | E55: 1 | F55: =VLOOKUP(A:A,'SOS VS SOM'!A:E,4,FALSE) -> 1 | G55: =AVERAGE(B55:F55) -> 0.68 | H55: =IF(G55>=60%,"pay","don't pay") -> pay
A56: Family Fresh (Eco Gas) | B56: 0 | C56: 0.4 | D56: 0.98666667 | E56: 1 | F56: =VLOOKUP(A:A,'SOS VS SOM'!A:E,4,FALSE) -> 0 | G56: =AVERAGE(B56:F56) -> 0.47733333 | H56: =IF(G56>=60%,"pay","don't pay") -> don't pay
A57: Fraine Gayaza Road | B57: 0 | C57: 0.4 | D57: 1 | E57: 1 | F57: =VLOOKUP(A:A,'SOS VS SOM'!A:E,4,FALSE) -> 0 | G57: =AVERAGE(B57:F57) -> 0.48 | H57: =IF(G57>=60%,"pay","don't pay") -> don't pay
A58: Fraine Kansanga | B58: 1 | C58: 0.4 | D58: 1 | E58: 1 | F58: =VLOOKUP(A:A,'SOS VS SOM'!A:E,4,FALSE) -> 0 | G58: =AVERAGE(B58:F58) -> 0.68 | H58: =IF(G58>=60%,"pay","don't pay") -> pay
...

Sheet SOS VS SOM
A1: OUTLETS | B1: % SOS | C1: %SOM | D1: SOS VS SOM | E1: Pay status
A2: Apple Door To Door Supermarket | B2: 0.29525 | C2: 0.44153846 | D2: 0 | E2: =IF(Table1[[#This Row],[SOS VS SOM]]=100%,"Pay","Don't pay") -> Don't pay
A3: Bea Mart (U) Ltd | B3: 0.40875 | C3: 0.40133333 | D3: 1 | E3: =IF(Table1[[#This Row],[SOS VS SOM]]=100%,"Pay","Don't pay") -> Pay
A4: Benco Liner Supermarket Ltd | B4: 0.3459375 | C4: 0.40083333 | D4: 0 | E4: =IF(Table1[[#This Row],[SOS VS SOM]]=100%,"Pay","Don't pay") -> Don't pay
A5: Capital Shoppers Garden City | B5: 0.19354167 | C5: 0.33928571 | D5: 0 | E5: =IF(Table1[[#This Row],[SOS VS SOM]]=100%,"Pay","Don't pay") -> Don't pay
A6: Capital Shoppers Supermarket - Ntinda | B6: 0.2625 | C6: 0.432 | D6: 0 | E6: =IF(Table1[[#This Row],[SOS VS SOM]]=100%,"Pay","Don't pay") -> Don't pay
A7: Carrefour Uganda - Acacia Mall | B7: 0.18895833 | C7: 0.29933333 | D7: 0 | E7: =IF(Table1[[#This Row],[SOS VS SOM]]=100%,"Pay","Don't pay") -> Don't pay
A8: Carrefour Uganda - Naalya | B8: 0.22 | C8: 0.305 | D8: 0 | E8: =IF(Table1[[#This Row],[SOS VS SOM]]=100%,"Pay","Don't pay") -> Don't pay
A9: Carrefour Victoria Mall | B9: 0.19 | C9: 0.28857143 | D9: 0 | E9: =IF(Table1[[#This Row],[SOS VS SOM]]=100%,"Pay","Don't pay") -> Don't pay
A10: Carrefour village mall | B10: 0.2275 | C10: 0.366 | D10: 0 | E10: =IF(Table1[[#This Row],[SOS VS SOM]]=100%,"Pay","Don't pay") -> Don't pay
A11: City joy supermarket Kireka | B11: 0.33625 | C11: 0.49307692 | D11: 0 | E11: =IF(Table1[[#This Row],[SOS VS SOM]]=100%,"Pay","Don't pay") -> Don't pay
A12: Cynibel General Trading Limited (B | B12: 0.220625 | C12: 0.30384615 | D12: 0 | E12: =IF(Table1[[#This Row],[SOS VS SOM]]=100%,"Pay","Don't pay") -> Don't pay
A13: Cynibel Super Market | B13: 0.304375 | C13: 0.35071429 | D13: 0 | E13: =IF(Table1[[#This Row],[SOS VS SOM]]=100%,"Pay","Don't pay") -> Don't pay
... A141: Dine and Save | B141: 0.31375 | C141: 0.48866667 | D141: 0 | E141: =IF(Table1[[#This Row],[SOS VS SOM]]=100%,"Pay","Don't pay") -> Don't pay

Sheet PVT
A3: Sum of Home care | B3: Column Labels
A4: Row Labels | B4: Center Alignment | C4: NPD | D4: OSA | E4: POSM
A5: 2k shoppers | B5: 1 | C5: 0.77777778 | D5: 1 | E5: 1
A6: Abra Shopping Centre | B6: 1 | C6: 1 | D6: 1 | E6: 1
A7: Abrah supermarket | B7: 1 | C7: 0.4 | D7: 1 | E7: 1
A8: Active supermarket | B8: 1 | C8: 1 | D8: 1 | E8: 1
A9: Apple Door To Door Supermarket | B9: 1 | C9: 0.45454545 | D9: 0.85925926 | E9: 1
A10: Bam Shopping Centre | B10: 0 | C10: 0.4 | D10: 1 | E10: 1
A11: Bea Mart (U) Ltd | B11: 1 | C11: 0.4 | D11: 1 | E11: 1
A12: Benco Liner Supermarket Ltd | B12: 1 | C12: 1 | D12: 1 | E12: 1
A13: Bengel | B13: 1 | C13: 0.63636364 | D13: 1 | E13: 1
A14: Best Buy Bukoto | B14: 1 | C14: 0.85 | D14: 0.9962963 | E14: 1
A15: CAC KYANJA | B15: 1 | C15: 0.55 | D15: 0.97083333 | E15: 1
A16: Capital Shoppers Garden City | B16: 0 | C16: 0.22222222 | D16: 0.94153846 | E16: 1
... A30: China Town Lugogo Mall | B30: 1 | C30: 0.86363636 | D30: 0.96439628 | E30: 1
A31: Citizen supermarket | D31: 1
A32: City Joy Kitintale | B32: 1 | C32: 0.9 | D32: 1 | E32: 1
A33: City Joy Kitintale | B33: 1 | C33: 0.4 | D33: 1 | E33: 1
A34: City Joy Mbuya | B34: 1 | C34: 0.64 | D34: 0.96666667 | E34: 1
A35: City joy supermarket Kireka | B35: 1 | C35: 0.4 | D35: 0.97666667 | E35: 1
A36: City Shoppers Supermarket | B36: 1 | C36: 1 | D36: 0.8047619 | E36: 1
A37: Cobrena supermarket | D37: 0.97037037
A38: Costco | C38: 0.4 | D38: 1 | E38: 1
A39: Crane Shoppers | B39: 1 | C39: 0.55 | D39: 1 | E39: 1
A40: Crown Stores Lubowa | D40: 1
A41: Crown Stores Sonde | B41: 1 | C41: 0.44444444 | D41: 0.82380952 | E41: 1
A42: Cynibel General Trading Limited (B | B42: 1 | C42: 1 | D42: 0.99342105 | E42: 1
A43: Cynibel General Trading Ltd ( Lweza | B43: 0 | C43: 0.88888889 | D43: 1 | E43: 1
A44: Cynibel Kiwatule | B44: 1 | C44: 0.64705882 | D44: 0.96666667 | E44: 1
A45: Cynibel Super Market | B45: 1 | C45: 1 | D45: 0.99885584 | E45: 1
A46: Day Day life supermarket | B46: 1 | C46: 0.4 | D46: 1 | E46: 1
A47: Day To Day Uganda Limited | B47: 1 | C47: 0.4 | D47: 0.9122807 | E47: 1
A48: DE PENTA | B48: 0 | C48: 0.45454545 | D48: 0.43809524 | E48: 1
A49: Deluxe Supermarket | B49: 1 | C49: 0.36363636 | D49: 0.98888889 | E49: 1
A50: Dembe smkt | B50: 1 | C50: 0.86363636 | D50: 1 | E50: 1
A51: Dine and Save | B51: 1 | C51: 1 | D51: 0.99583333 | E51: 1
A52: Dine And Save Supermarket | B52: 1 | C52: 1 | D52: 0.96666667 | E52: 1
... A58: Equity Shoppers Supermarket | B58: 1 | C58: 1 | D58: 0.96666667 | E58: 1
A59: Fabulous Freeman | C59: 0.59090909 | D59: 1 | E59: 1
A60: Fabulous Freeman Supermarket | B60: 0 | C60: 0.4 | D60: 1 | E60: 1
...

Sheet RAW DATA
B2: OUTLET NAME | C2: CHANNEL | D2: DISTRIBUTOR | E2: Home care | F2: Personal care | G2: Beauty and well being | H2: Foods | I2: Score | J2: KPI
B3: 2k shoppers | C3: Lmt Account | D3: Dredro Distributors | E3: 1 | F3: 1 | G3: 1 | H3: 1 | I3: 1 | J3: OSA
B4: Abra Shopping Centre | C4: Lmt Account | D4: Qima Ventures Enterprises | E4: 1 | F4: 1 | G4: 1 | H4: 1 | I4: 1 | J4: OSA
B5: Abrah supermarket | C5: Lmt Account | D5: Dredro Distributors | E5: 1 | F5: 1 | G5: 1 | H5: 0.88888889 | I5: 0.97222222 | J5: OSA
B6: Active supermarket | C6: Lmt Account | D6: Gt Trading Limited | E6: 1 | F6: 1 | G6: 1 | H6: 1 | I6: 1 | J6: OSA
B7: Apple Door To Door Supermarket | C7: Lmt Account | D7: Falkan Investments Ltd Mbarara | E7: 0.85925926 | F7: 1 | G7: 1 | H7: 0.64197531 | I7: 0.87530864 | J7: OSA
B8: Bam Shopping Centre | C8: Lmt Account | D8: Qima Ventures Enterprises | E8: 1 | F8: 1 | G8: 1 | H8: 1 | I8: 1 | J8: OSA
B9: Bea Mart (U) Ltd | C9: Lmt Account | D9: Salvo Grima Fortportal | E9: 1 | F9: 1 | G9: 1 | H9: 1 | I9: 1 | J9: OSA
B10: Benco Liner Supermarket Ltd | C10: Lmt Account | D10: Zeripen Investments Limited | E10: 1 | F10: 1 | G10: 1 | H10: 1 | I10: 1 | J10: OSA
B11: Bengel | C11: Lmt Account | D11: Qima Ventures Enterprises | E11: 1 | F11: 1 | G11: 1 | H11: 1 | I11: 1 | J11: OSA
B12: Best Buy Bukoto | C12: Lmt Account | D12: Salvo Grima Kampala | E12: 0.9962963 | F12: 1 | G12: 1 | H12: 1 | I12: 0.99907407 | J12: OSA
B13: CAC KYANJA | C13: Lmt Account | D13: Salvo Grima Kampala | E13: 0.97083333 | F13: 1 | G13: 1 | H13: 1 | I13: 0.99270833 | J13: OSA
B14: Capital Shoppers Garden City | C14: Capital Account | D14: Dhl | E14: 0.94153846 | F14: 1 | G14: 0.96 | H14: 0.98222222 | I14: 0.97094017 | J14: OSA
... B164: Wilsen Supermarket | C164: Lmt Account | D164: Davakam Collections Ltd Kampala | E164: 0.98095238 | F164: 0.98571429 | G164: 0.87662338 | H164: 0.82539683 | I164: 0.91717172 | J164: OSA
B165: 2k shoppers | C165: Lmt Account | D165: Dredro Distributors | E165: 0.77777778 | F165: 1 | I165: 0.88888889 | J165: NPD
B166: Abra Shopping Centre | C166: Lmt Account | D166: Qima Ventures Enterprises | E166: 1 | F166: 1 | I166: 1 | J166: NPD
B167: Abrah supermarket | C167: Lmt Account | D167: Dredro Distributors | E167: 0.4 | F167: 1 | I167: 0.7 | J167: NPD
B168: Active supermarket | C168: Lmt Account | D168: Gt Trading Limited | E168: 1 | F168: 1 | I168: 1 | J168: NPD
B169: Apple Door To Door Supermarket | C169: Lmt Account | D169: Falkan Investments Ltd Mbarara | E169: 0.45454545 | F169: 1 | I169: 0.72727273 | J169: NPD
B170: Bam Shopping Centre | C170: Lmt Account | D170: Qima Ventures Enterprises | E170: 0.4 | F170: 1 | I170: 0.7 | J170: NPD
B171: Bea Mart (U) Ltd | C171: Lmt Account | D171: Salvo Grima Fortportal | E171: 0.4 | F171: 1 | I171: 0.7 | J171: NPD
B172: Benco Liner Supermarket Ltd | C172: Lmt Account | D172: Zeripen Investments Limited | E172: 1 | F172: 1 | I172: 1 | J172: NPD
B173: Bengel | C173: Lmt Account | D173: Qima Ventures Enterprises | E173: 0.63636364 | F173: 1 | I173: 0.81818182 | J173: NPD
B174: Best Buy Bukoto | C174: Lmt Account | D174: Salvo Grima Kampala | E174: 0.85 | F174: 1 | I174: 0.925 | J174: NPD
B175: CAC KYANJA | C175: Lmt Account | D175: Salvo Grima Kampala | E175: 0.55 | F175: 1 | I175: 0.775 | J175: NPD
B176: Capital Shoppers Garden City | C176: Capital Account | D176: Dhl | E176: 0.22222222 | F176: 1 | I176: 0.61111111 | J176: NPD
... B314: Wilsen Supermarket | C314: Lmt Account | D314: Davakam Collections Ltd Kampala | E314: 0.4 | F314: 1 | I314: 0.7 | J314: NPD
B315: 2k shoppers | C315: Lmt Account | D315: Dredro Distributors | E315: 1 | F315: 1 | G315: 1 | H315: 1 | I315: 1 | J315: POSM
B316: Abra Shopping Centre | C316: Lmt Account | D316: Qima Ventures Enterprises | E316: 1 | F316: 1 | G316: 1 | H316: 1 | I316: 1 | J316: POSM
B317: Abrah supermarket | C317: Lmt Account | D317: Dredro Distributors | E317: 1 | F317: 1 | G317: 1 | H317: 1 | I317: 1 | J317: POSM
B318: Active supermarket | C318: Lmt Account | D318: Gt Trading Limited | E318: 1 | F318: 1 | G318: 1 | H318: 1 | I318: 1 | J318: POSM
B319: Apple Door To Door Supermarket | C319: Lmt Account | D319: Falkan Investments Ltd Mbarara | E319: 1 | F319: 1 | G319: 1 | H319: 1 | I319: 1 | J319: POSM
B320: Bam Shopping Centre | C320: Lmt Account | D320: Qima Ventures Enterprises | E320: 1 | F320: 1 | G320: 1 | H320: 1 | I320: 1 | J320: POSM
B321: Bea Mart (U) Ltd | C321: Lmt Account | D321: Salvo Grima Fortportal | E321: 1 | F321: 1 | G321: 1 | H321: 1 | I321: 1 | J321: POSM
B322: Benco Liner Supermarket Ltd | C322: Lmt Account | D322: Zeripen Investments Limited | E322: 1 | F322: 1 | G322: 1 | H322: 1 | I322: 1 | J322: POSM
B323: Bengel | C323: Lmt Account | D323: Qima Ventures Enterprises | E323: 1 | F323: 1 | G323: 1 | H323: 1 | I323: 1 | J323: POSM
B324: Best Buy Bukoto | C324: Lmt Account | D324: Salvo Grima Kampala | E324: 1 | F324: 1 | G324: 1 | H324: 1 | I324: 1 | J324: POSM
B325: CAC KYANJA | C325: Lmt Account | D325: Salvo Grima Kampala | E325: 1 | F325: 1 | G325: 1 | H325: 1 | I325: 1 | J325: POSM
B326: Capital Shoppers Garden City | C326: Capital Account | D326: Dhl | E326: 1 | F326: 1 | G326: 1 | H326: 1 | I326: 1 | J326: POSM
... B464: Wilsen Supermarket | C464: Lmt Account | D464: Davakam Collections Ltd Kampala | E464: 1 | F464: 1 | G464: 1 | H464: 1 | I464: 1 | J464: POSM
...
